<robot name="my_robot">
  <!-- Base link -->
  <link name="base_link">
    <visual>
      <origin xyz="0 0 0" rpy="0 0 0"/> <!-- Position the base -->
      <geometry>
        <mesh filename="Base_centered.stl" scale="0.001 0.001 0.001"/>
      </geometry>
    </visual>
    <collision>
      <origin xyz="0.4 0 0.2" rpy="0 0 0"/> 
      <geometry>
        <box size="1.8 1.0 0.3"/>  <!-- Adjust size to fit the base -->
      </geometry>
    </collision>
  </link>

  <!-- Joint 1: Revolute joint in Z-axis -->
  <joint name="joint_1" type="revolute">
    <parent link="base_link"/>
    <child link="link_0"/>
    <origin xyz="0 0 0" rpy="0 0 0"/> <!-- Adjust as necessary -->
    <axis xyz="0 0 1"/> <!-- Rotation along Z-axis -->
    <limit effort="100" velocity="1.0" lower="-3.14" upper="3.14"/>
  </joint>

  <!-- Link 0 -->
  <link name="link_0">
    <visual>
      <origin xyz="0 0 0" rpy="0 0 0"/> <!-- Ensure this is correct -->
      <geometry>
        <mesh filename="Link1_centered.stl" scale="0.001 0.001 0.001"/>
      </geometry>
    </visual>
    <collision>
      <origin xyz="0 0 0" rpy="0 0 0"/>
      <geometry>
        <box size="0 0 0"/>  <!-- Adjust size to fit Link 0 -->
      </geometry>
    </collision>
  </link>

  <!-- Joint 2: Revolute joint in Y-axis -->
  <joint name="joint_2" type="revolute">
    <parent link="link_0"/>
    <child link="link_1"/>
    <origin xyz="0 0 0.73" rpy="0 0 0"/> <!-- Adjust as necessary -->
    <axis xyz="0 1 0"/> <!-- Rotation along Y-axis -->
    <limit effort="100" velocity="1.0" lower="-3.14" upper="0"/> <!-- Reversed limits -->
  </joint>

  <!-- Link 1 -->
  <link name="link_1">
    <visual>
      <origin xyz="0 0 0" rpy="0 0 0"/> <!-- Ensure this is correct -->
      <geometry>
        <mesh filename="Link2_centered.stl" scale="0.001 0.001 0.001"/>
      </geometry>
    </visual>
    <collision>
      <origin xyz="0.5 0 0" rpy="0 0 0"/>
      <geometry>
        <box size="0.8 0.6 0.4"/>  <!-- Adjust size to fit Link 1 -->
      </geometry>
    </collision>
  </link>

  <!-- Joint 3: Revolute joint in Y-axis -->
  <joint name="joint_3" type="revolute">
    <parent link="link_1"/>
    <child link="link_2"/>
    <origin xyz="0.90 0 0" rpy="0 0 0"/> <!-- Adjust as necessary -->
    <axis xyz="0 1 0"/> <!-- Rotation along Y-axis -->
    <limit effort="100" velocity="1.0" lower="0" upper="1.57"/>
  </joint>

  <!-- Link 2 -->
  <link name="link_2">
    <visual>
      <origin xyz="0 0 0" rpy="0 0 0"/> <!-- Ensure this is correct -->
      <geometry>
        <mesh filename="Link3_centered.stl" scale="0.001 0.001 0.001"/>
      </geometry>
    </visual>
    <collision>
      <origin xyz="-0.3 0 0.4" rpy="0 0 0"/>
      <geometry>
        <box size="1 0.5 0.25"/>  <!-- Adjust size to fit Link 2 -->
      </geometry>
    </collision>
  </link>

  <!-- Joint 4: Revolute joint in Y-axis -->
  <joint name="joint_4" type="revolute">
    <parent link="link_2"/>
    <child link="end_effector"/>
    <origin xyz="-0.83 0 0.35" rpy="0 0 0"/> <!-- Adjust as necessary -->
    <axis xyz="0 1 0"/> <!-- Rotation along Y-axis -->
    <limit effort="100" velocity="1.0" lower="-1.57" upper="1.57"/>
  </joint>

  <!-- End-Effector -->
  <link name="end_effector">
    <visual>
      <origin xyz="0 0 0" rpy="0 0 0"/> <!-- Ensure this is correct -->
      <geometry>
        <mesh filename="EndEffector_centered.stl" scale="0.001 0.001 0.001"/>
      </geometry>
    </visual>
    <collision>
      <origin xyz="-0.3 0 0" rpy="0 0 0"/>
      <geometry>
        <box size="0.2 0.5 0.3"/>  <!-- Adjust size to fit Link 2 -->
      </geometry>
    </collision>
  </link>
</robot>

 
